Workbook
Name Slicer_City: #N/A

Sheet CUISINE EXPANDED
A1: City | B1: Food type
A2: Bangalore | B2: Biryani
A3: Bangalore | B3: Chinese
A4: Bangalore | B4: North Indian
A5: Bangalore | B5: South Indian
A6: Bangalore | B6: Mughlai | E6: Count of Food type | F6: Column Labels
A7: Bangalore | B7: Lucknowi | E7: Row Labels | F7: Afghani | G7: African | H7: American | I7: American,Beverages,Fast Food | J7: American,Chinese,Continental,Desserts | K7: American,Chinese,Indian | L7: American,Continental | M7: American,Continental,Italian,Pastas,Snacks,Desserts,Beverages | N7: American,European,Continental | O7: American,Fast Food | P7: American,Fast Food,Beverages | Q7: American,Fast Food,Italian,Mexican,Beverages | R7: American,Mexican,Indian,Fast Food,Snacks,Combo | S7: American,Pastas,Snacks,Desserts,Beverages,North Indian,Asian | T7: American,Snacks | U7: American,Snacks,Beverages | V7: Andhra | W7: Arabian | X7: Arabian,Biryani,Mughlai | Y7: Arabian,Fast Food | Z7: Arabian,Street Food | AA7: Asian | AB7: Asian,Chinese | AC7: Asian,Chinese,Combo,Desserts,Indian,North Indian | AD7: Asian,Chinese,Pan-Asian,Thai,Oriental,Indonesian,Seafood,Desserts,Combo | AE7: Asian,Chinese,Seafood | AF7: Asian,European,Italian | AG7: Asian,Fast Food,Chinese,Combo | AH7: Asian,North Indian,Continental,Healthy Food,Punjabi,Home Food,Oriental,Desserts,Beverages,Pan-Asian,Bengali,Mangalorean,Kashmiri,Lucknowi,Chinese,Sweets,Kebabs,Combo,Rajasthani,Awadhi | AI7: Assamese | AJ7: Attractive Combos Available | AK7: Australian | AL7: Awadhi | AM7: Bakery | AN7: Bakery,Beverages | AO7: Bakery,Combo,Beverages,Maharashtrian,Snacks,Street Food,South Indian,Punjabi,Fast Food | AP7: Bakery,Continental | AQ7: Bakery,Continental,Salads,Pastas,European,Desserts | AR7: Bakery,Desserts | AS7: Bakery,Desserts,Australian,Snacks | AT7: Bakery,Desserts,Beverages | AU7: Bakery,Desserts,Beverages,Snacks | AV7: Bakery,Desserts,Fast Food | AW7: Bakery,Desserts,Fast Food,Snacks | AX7: Bakery,Desserts,Ice Cream | AY7: Bakery,Desserts,Snacks | AZ7: Bakery,Desserts,Snacks,Beverages,Waffle | BA7: Bakery,Desserts,Sweets | BB7: Bakery,Fast Food | BC7: Bakery,Fast Food,Snacks | BD7: Bakery,Fast Food,Snacks,Beverages | BE7: Bakery,Indian,Combo,Desserts | BF7: Bakery,Pizzas | BG7: Bakery,Pizzas,Fast Food,Beverages | BH7: Bakery,Pizzas,Haleem | BI7: Bakery,Snacks | BJ7: Bakery,Snacks,Desserts | BK7: Bakery,Sweets,Desserts | BL7: Bangladeshi | BM7: Barbecue | BN7: Bengali | BO7: Bengali,Chinese | BP7: Bengali,Fast Food | BQ7: Bengali,Indian,Combo | BR7: Bengali,Italian,Chinese,Combo,Snacks,Kebabs,Indian | BS7: Bengali,Snacks,Indian | BT7: Beverages | BU7: Beverages,Chaat,Desserts,Fast Food,Juices | BV7: Beverages,Desserts | BW7: Beverages,Desserts,American,Fast Food | BX7: Beverages,Desserts,Healthy Food,Juices,Salads,Ice Cream | BY7: Beverages,Fast Food | BZ7: Beverages,Fast Food,Mexican,Indian,Snacks | CA7: Beverages,Fast Food,North Indian,South Indian | CB7: Beverages,Ice Cream | CC7: Beverages,Ice Cream,Desserts | CD7: Beverages,Ice Cream,Desserts,Healthy Food | CE7: Beverages,Ice Cream,Fast Food | CF7: Beverages,Ice Cream,Salads | CG7: Beverages,Italian | CH7: Beverages,Juices,Fast Food | CI7: Beverages,Snacks | CJ7: Beverages,Snacks,Desserts | CK7: Beverages,South Indian | CL7: Bihari | CM7: Biryani | CN7: Biryani,Beverages | CO7: Biryani,Chinese | CP7: Biryani,Desserts,North Indian,Chinese,Ice Cream,Mughlai,Fast Food | CQ7: Biryani,Hyderabadi,Lucknowi,North Indian,Mughlai,Combo,Desserts | CR7: Biryani,Indian | CS7: Biryani,Indian,Hyderabadi,Fast Food,Haleem | CT7: Biryani,Indian,Mughlai | CU7: Biryani,Indian,North Indian | CV7: Biryani,Indian,Tandoor,Punjabi | CW7: Biryani,Kebabs | CX7: Biryani,Mughlai | CY7: Biryani,Mughlai,Lucknowi,Hyderabadi,Kebabs,North Indian,Persian,Desserts | CZ7: Biryani,Mughlai,North Indian,Indian,Kebabs,Tandoor,Awadhi | DA7: Biryani,North Indian | DB7: Biryani,North Indian,Chinese | DC7: Biryani,North Indian,Chinese,Mughlai,Tandoor | DD7: Biryani,North Indian,Chinese,Tandoor | DE7: Biryani,North Indian,Desserts | DF7: Bowl Company | DG7: British | DH7: Burmese | DI7: Cafe | DJ7: Cafe,Desserts,Beverages | DK7: Cafe,Desserts,Chinese | DL7: Cafe,Italian,Pizzas,Fast Food,Combo,Beverages,Desserts | DM7: Chaat | DN7: Chaat,Beverages,Juices | DO7: Chaat,Fast Food | DP7: Chaat,Snacks,Beverages | DQ7: Chaat,Street Food,Beverages,Home Food,Salads,Snacks | DR7: Chettinad | DS7: Chinese | DT7: Chinese,Asian | DU7: Chinese,Asian,Korean,Pan-Asian,Seafood,Thai,Japanese,Sushi,Burmese,Tibetan | DV7: Chinese,Asian,Oriental,Tibetan,Desserts | DW7: Chinese,Asian,Thai | DX7: Chinese,Beverages | DY7: Chinese,Biryani,Indian | DZ7: Chinese,Biryani,Indian,Tandoor,Desserts | EA7: Chinese,Biryani,Tandoor | EB7: Chinese,Continental | EC7: Chinese,Continental,Fast Food,Desserts | ED7: Chinese,Continental,Indian,Beverages | EE7: Chinese,Continental,Italian,Mediterranean,Thai,Lebanese,American,Asian,Beverages,Bakery,Biryani,Desserts,Mexican,North Indian,Salads,Pizzas | EF7: Chinese,Continental,Thai | EG7: Chinese,Fast Food | EH7: Chinese,Fast Food,North Indian | EI7: Chinese,Fast Food,Pizzas,Snacks | EJ7: Chinese,Indian | EK7: Chinese,Indian,Asian,Biryani,Snacks,Beverages,Desserts | EL7: Chinese,Indian,Beverages | EM7: Chinese,Indian,Biryani | EN7: Chinese,Indian,Pastas | EO7: Chinese,Indian,Snacks | EP7: Chinese,Indian,Thalis,Beverages | EQ7: Chinese,Italian | ER7: Chinese,Italian,Desserts,Bakery,Fast Food | ES7: Chinese,Japanese,Pan-Asian,Tibetan,Asian,Beverages | ET7: Chinese,Kerala | EU7: Chinese,Lebanese,Kebabs,Mughlai,Indian | EV7: Chinese,Lebanese,Pizzas | EW7: Chinese,North Indian | EX7: Chinese,North Indian,Biryani,Desserts | EY7: Chinese,North Indian,Biryani,Sweets | EZ7: Chinese,North Indian,Continental,Fast Food,Snacks | FA7: Chinese,North Indian,Continental,Pan-Asian,Italian,American,Tandoor,Fast Food,Desserts | FB7: Chinese,North Indian,Fast Food,Beverages | FC7: Chinese,North Indian,Fast Food,Mughlai,Indian,Seafood,Kebabs,Thalis | FD7: Chinese,North Indian,Fast Food,Snacks,Beverages | FE7: Chinese,North Indian,Seafood | FF7: Chinese,North Indian,Seafood,Pan-Asian | FG7: Chinese,North Indian,Tandoor,Biryani,Beverages,Desserts | FH7: Chinese,Pan-Asian,Asian,Beverages,Desserts | FI7: Chinese,Pan-Asian,Tibetan,Oriental,Mongolian | FJ7: Chinese,Seafood | FK7: Chinese,Snacks | FL7: Chinese,Snacks,Italian | FM7: Chinese,South Indian | FN7: Chinese,South Indian,Fast Food | FO7: Chinese,Tandoor,Biryani | FP7: Chinese,Tandoor,Fast Food,Indian | FQ7: Chinese,Thai | FR7: Chinese,Thai,Asian | FS7: Chinese,Thai,Asian,Oriental | FT7: Chinese,Thai,Fast Food | FU7: Chinese,Thai,Indonesian,Combo | FV7: Chinese,Thai,Korean,Seafood | FW7: Chinese,Tibetan,Nepalese,Pizzas,Snacks,Beverages,Combo | FX7: Coastal | FY7: Coastal,Indian,Seafood | FZ7: Combo | GA7: Combo,Snacks,Beverages,Desserts,Indian | GB7: Continental | GC7: Continental,Bakery,Desserts | GD7: Continental,Bakery,Pan-Asian | GE7: Continental,Beverages,Ice Cream | GF7: Continental,Chinese | GG7: Continental,Fast Food,North Indian | GH7: Continental,Fast Food,North Indian,Street Food | GI7: Continental,Healthy Food,Indian | GJ7: Continental,Indian | GK7: Continental,Indian,Chinese | GL7: Continental,Indian,Chinese,Snacks,Beverages | GM7: Continental,Indian,Desserts | GN7: Continental,Italian | GO7: Continental,Italian,Chinese | GP7: Continental,Italian,Chinese,Beverages | GQ7: Continental,Italian,Desserts | GR7: Continental,Italian,Fast Food,Beverages,Desserts | GS7: Continental,Italian,Indian,Chinese | GT7: Continental,Lebanese | GU7: Continental,North Indian,South Indian,Beverages | GV7: Desserts | GW7: Desserts,Bakery | GX7: Desserts,Bakery,Beverages | GY7: Desserts,Bakery,Fast Food | GZ7: Desserts,Bakery,Ice Cream | HA7: Desserts,Bakery,Snacks | HB7: Desserts,Bakery,Sweets | HC7: Desserts,Beverages | HD7: Desserts,Beverages,Pizzas | HE7: Desserts,Biryani,Chaat,Fast Food | HF7: Desserts,Continental,Italian | HG7: Desserts,Fast Food,Bakery | HH7: Desserts,Haleem,Home Food,Healthy Food,Fast Food,Sweets,Beverages | HI7: Desserts,Ice Cream | HJ7: Desserts,Ice Cream,Bakery | HK7: Desserts,Ice Cream,Beverages | HL7: Desserts,Ice Cream,Chaat | HM7: Desserts,Pizzas | HN7: Desserts,Snacks | HO7: Desserts,Snacks,Bakery | HP7: Desserts,Snacks,Fast Food,Beverages,Combo | HQ7: Desserts,Sweets | HR7: European | HS7: Fast Food | HT7: Fast Food,Bakery,Desserts,Beverages | HU7: Fast Food,Beverages | HV7: Fast Food,Beverages,Desserts | HW7: Fast Food,Beverages,Thalis | HX7: Fast Food,Chinese,Asian,Thai,Oriental,Pan-Asian,Seafood,Combo | HY7: Fast Food,Combo | HZ7: Fast Food,Combo,Desserts,Beverages | IA7: Fast Food,Combo,Indian | IB7: Fast Food,Continental,Beverages | IC7: Fast Food,Continental,Chinese | ID7: Fast Food,Desserts | IE7: Fast Food,Desserts,Beverages | IF7: Fast Food,Healthy Food,Salads,Snacks,Desserts,Beverages | IG7: Fast Food,Indian,Chaat,North Indian,Jain,Mughlai,Snacks,Desserts | IH7: Fast Food,Italian,Beverages | II7: Fast Food,Italian,Mexican,Beverages | IJ7: Fast Food,Middle Eastern,Cafe | IK7: Fast Food,North Indian | IL7: Fast Food,Pastas,Pizzas | IM7: Fast Food,Pizzas | IN7: Fast Food,Pizzas,Beverages,Desserts | IO7: Fast Food,Pizzas,Pastas,Beverages,Desserts | IP7: Fast Food,Salads,Snacks,Desserts,Beverages | IQ7: Fast Food,Snacks | IR7: Fast Food,Snacks,Beverages | IS7: Fast Food,Snacks,Beverages,Combo | IT7: Fast Food,Snacks,Indian,Beverages | IU7: Fast Food,Snacks,North Indian,Mexican,Beverages | IV7: Fast Food,Street Food,Arabian | IW7: French | IX7: German | IY7: Goan | IZ7: Goan,Seafood | JA7: Greek | JB7: Grill | JC7: Gujarati | JD7: Haleem | JE7: Healthy Food | JF7: Healthy Food,Continental,Indian,Chinese | JG7: Healthy Food,Continental,Keto,Indian,Salads | JH7: Healthy Food,Indian,Keto,Snacks,Bakery,North Indian | JI7: Healthy Food,Juices,Beverages,Snacks,Fast Food | JJ7: Healthy Food,Juices,Continental | JK7: Healthy Food,Keto,Desserts,Ice Cream,Beverages,Snacks,Bakery | JL7: Healthy Food,Keto,North Indian,Continental | JM7: Healthy Food,Pizzas,North Indian,Thalis,Biryani | JN7: Healthy Food,Salads,Chaat | JO7: Healthy Food,Salads,Continental | JP7: Healthy Food,Snacks,Desserts | JQ7: Healthy Food,South Indian | JR7: Home Food | JS7: Home Food,North Indian | JT7: Home Food,North Indian,Healthy Food,Thalis,Desserts,Indian,Punjabi | JU7: Hyderabadi | JV7: Hyderabadi,Biryani,Beverages | JW7: Ice Cream | JX7: Ice Cream Cakes | JY7: Ice Cream Cakes,Desserts,Bakery,Sweets,Beverages | JZ7: Ice Cream,Beverages | KA7: Ice Cream,Beverages,Fast Food | KB7: Ice Cream,Desserts | KC7: Ice Cream,Desserts,Bakery | KD7: Ice Cream,Desserts,Beverages | KE7: Ice Cream,Desserts,Beverages,Ice Cream Cakes | KF7: Ice Cream,Ice Cream Cakes,Desserts | KG7: Indian | KH7: Indian,Bakery | KI7: Indian,Biryani | KJ7: Indian,Biryani,Chinese,Beverages,Seafood,Tandoor | KK7: Indian,Biryani,Tandoor | KL7: Indian,Chinese | KM7: Indian,Chinese,Combo | KN7: Indian,Chinese,Continental | KO7: Indian,Chinese,Desserts,Juices | KP7: Indian,Chinese,Fast Food | KQ7: Indian,Chinese,Fast Food,American,Biryani,Combo | KR7: Indian,Chinese,Ice Cream | KS7: Indian,Chinese,Italian | KT7: Indian,Chinese,Kebabs,Fast Food,Combo | KU7: Indian,Chinese,Mangalorean | KV7: Indian,Chinese,North Indian | KW7: Indian,Chinese,Pizzas,Italian | KX7: Indian,Chinese,Pizzas,Pastas,Snacks,Biryani,Continental,Beverages,Desserts | KY7: Indian,Chinese,Seafood | KZ7: Indian,Chinese,Snacks | LA7: Indian,Chinese,South Indian,Bengali,Snacks | LB7: Indian,Chinese,South Indian,Biryani,Tandoor,Snacks | LC7: Indian,Chinese,South Indian,Continental | LD7: Indian,Chinese,Tandoor | LE7: Indian,Chinese,Tandoor,Punjabi | LF7: Indian,Chinese,Tandoor,Seafood | LG7: Indian,Chinese,Tandoor,South Indian | LH7: Indian,Continental,Beverages,Fast Food | LI7: Indian,Continental,Snacks,Sweets | LJ7: Indian,Desserts,Fast Food | LK7: Indian,Fast Food | LL7: Indian,Fast Food,Bakery | LM7: Indian,Fast Food,Beverages | LN7: Indian,Fast Food,Beverages,Combo,Chinese | LO7: Indian,Gujarati,Punjabi,Thalis | LP7: Indian,Home Food,Healthy Food,Snacks | LQ7: Indian,Mughlai,Chinese,Biryani,Punjabi | LR7: Indian,North Indian,Chinese,Biryani | LS7: Indian,North Indian,Chinese,Snacks,Chaat,Thalis,Combo | LT7: Indian,North Indian,Rajasthani,Thalis,Combo | LU7: Indian,North Indian,Tandoor,Mughlai,Desserts | LV7: Indian,Punjabi,North Indian,Mughlai,Seafood | LW7: Indian,Rajasthani | LX7: Indian,Seafood,Chinese,Ice Cream | LY7: Indian,Snacks | LZ7: Indian,Snacks,Fast Food,South Indian,Sweets,Beverages | MA7: Indian,Snacks,Thalis,Desserts | MB7: Indian,South Indian | MC7: Indian,South Indian,Beverages | MD7: Indian,South Indian,Chinese | ME7: Indian,South Indian,Chinese,Arabian | MF7: Indian,South Indian,Snacks | MG7: Indian,Tandoor,Biryani | MH7: Indian,Tandoor,Chinese,Mughlai | MI7: Indonesian | MJ7: Italian | MK7: Italian,American,Mexican,Pastas,Pizzas,Desserts,Salads,Snacks | ML7: Italian,Bakery | MM7: Italian,Beverages | MN7: Italian,Continental | MO7: Italian,Continental,Indian,Mexican | MP7: Italian,Continental,Snacks | MQ7: Italian,Desserts | MR7: Italian,Lebanese,Chinese,Indian,Mexican,Biryani,Pan-Asian,Asian,Salads,American | MS7: Italian,Pizzas | MT7: Italian,Pizzas,Desserts,Beverages,Combo | MU7: Italian,Pizzas,Pastas,Desserts,Beverages | MV7: Italian,Thai,Continental | MW7: Italian-American | MX7: Italian-American,European,Continental | MY7: Jain | MZ7: Japanese | NA7: Japanese,Mughlai,Chinese,North Indian,Biryani,Pan-Asian,Sushi,Seafood,Kebabs,Desserts | NB7: Juices | NC7: Juices,Beverages,Desserts | ND7: Juices,Beverages,Ice Cream | NE7: Juices,Desserts,Beverages | NF7: Juices,Fast Food | NG7: Juices,Healthy Food | NH7: Juices,Salads | NI7: Juices,Salads,Ice Cream,Snacks | NJ7: Kashmiri | NK7: Kebabs | NL7: Kerala | NM7: Keto | NN7: Keventers & more | NO7: Konkan | NP7: Korean | NQ7: Lebanese | NR7: Lebanese,Middle Eastern | NS7: Lebanese,Middle Eastern,Healthy Food,Mediterranean,Arabian | NT7: Lucknowi | NU7: Maharashtrian | NV7: Malaysian | NW7: Malwani | NX7: Mangalorean | NY7: Mangalorean,North Indian,South Indian,Malwani | NZ7: Mediterranean | OA7: Mexican | OB7: Mexican,American,Snacks | OC7: Mexican,Beverages | OD7: Middle Eastern | OE7: Mongolian | OF7: Mughlai | OG7: Mughlai,Arabian,Tandoor,Chinese,Seafood | OH7: Mughlai,Biryani,Indian,Tandoor,North Indian | OI7: Mughlai,Indian,Chinese,Tandoor | OJ7: Mughlai,North Indian | OK7: Mughlai,North Indian,Chinese | OL7: Mughlai,North Indian,Chinese,Seafood | OM7: Mughlai,North Indian,Chinese,South Indian | ON7: Mughlai,Seafood,Beverages | OO7: Mughlai,Tandoor,North Indian | OP7: Naga | OQ7: Navratri Special | OR7: Nepalese | OS7: North Eastern | OT7: North Indian | OU7: North Indian,Beverages,Fast Food,Snacks,Indian | OV7: North Indian,Biryani | OW7: North Indian,Biryani,Chinese,Desserts | OX7: North Indian,Chinese | OY7: North Indian,Chinese,Bengali | OZ7: North Indian,Chinese,Biryani | PA7: North Indian,Chinese,Biryani,Desserts | PB7: North Indian,Chinese,Biryani,Fast Food | PC7: North Indian,Chinese,Biryani,Fast Food,Desserts,Beverages | PD7: North Indian,Chinese,Biryani,Kebabs,Punjabi,Desserts,Indian,Asian,Pizzas,Thai,Jain | PE7: North Indian,Chinese,Biryani,South Indian,Fast Food | PF7: North Indian,Chinese,Continental | PG7: North Indian,Chinese,Continental,Mughlai,Seafood | PH7: North Indian,Chinese,Desserts,Continental,South Indian | PI7: North Indian,Chinese,Fast Food,Desserts | PJ7: North Indian,Chinese,Indian | PK7: North Indian,Chinese,Italian | PL7: North Indian,Chinese,Italian,Continental | PM7: North Indian,Chinese,Mughlai,Desserts,Fast Food | PN7: North Indian,Chinese,Mughlai,Fast Food,Desserts,Juices | PO7: North Indian,Chinese,Mughlai,Seafood | PP7: North Indian,Chinese,Mughlai,Tandoor,Desserts,Fast Food,Beverages | PQ7: North Indian,Chinese,Seafood | PR7: North Indian,Chinese,South Indian | PS7: North Indian,Chinese,South Indian,Jain | PT7: North Indian,Chinese,Tandoor | PU7: North Indian,Chinese,Tandoor,Sweets,Beverages | PV7: North Indian,Chinese,Thalis,Biryani | PW7: North Indian,Combo,Street Food,Fast Food,Beverages | PX7: North Indian,Desserts | PY7: North Indian,Desserts,Biryani | PZ7: North Indian,Fast Food,Chinese,Tandoor | QA7: North Indian,Fast Food,Tandoor,Biryani,Kebabs,Snacks,Chinese | QB7: North Indian,Indian,Continental | QC7: North Indian,Indian,Punjabi,Tandoor | QD7: North Indian,Malwani,Continental,South Indian,Chinese,Asian,Mughlai | QE7: North Indian,Mughlai | QF7: North Indian,Mughlai,Biryani,Beverages,Afghani,Desserts | QG7: North Indian,Mughlai,Chinese,Seafood | QH7: North Indian,Punjabi,Biryani,Combo,Chinese,Beverages,Desserts,Jain,Indian,Hyderabadi,Mughlai | QI7: North Indian,Punjabi,Combo,Biryani,Healthy Food,Jain,Thalis,Indian,Mughlai,Desserts | QJ7: North Indian,Punjabi,Home Food,Indian,Snacks,Combo,Desserts,Beverages,South Indian,Continental,Chettinad,Healthy Food,Chinese,Sweets | QK7: North Indian,Punjabi,Indian,Home Food,Combo,Beverages | QL7: North Indian,Punjabi,Street Food,Mughlai,Biryani,Tandoor,Arabian | QM7: North Indian,Rajasthani,Sweets,Chaat,Indian,Snacks,Street Food,Home Food | QN7: North Indian,Salads | QO7: North Indian,Seafood | QP7: North Indian,Seafood,Chinese | QQ7: North Indian,Sindhi,Punjabi,Thalis | QR7: North Indian,South Indian | QS7: North Indian,South Indian,Biryani,Tandoor | QT7: North Indian,South Indian,Chinese,Fast Food | QU7: North Indian,South Indian,Fast Food | QV7: North Indian,South Indian,Fast Food,Snacks,Thalis,Combo | QW7: North Indian,South Indian,Healthy Food,Juices | QX7: North Indian,Sweets | QY7: North Indian,Tandoor,Biryani | QZ7: North Indian,Tandoor,Chinese,Seafood,Biryani | RA7: North Indian,Tandoor,Punjabi,Seafood | RB7: Offer Valid only for New Customers | RC7: Oriental | RD7: Oriya | RE7: Paan | RF7: Paan,Indian | RG7: Paan,Sweets,Fast Food | RH7: Pan-Asian | RI7: Pan-Asian,Chinese,Asian,Thai,Malaysian,Tibetan | RJ7: Parsi | RK7: Pastas | RL7: Pastas,Beverages,Fast Food | RM7: Persian | RN7: Pizzas | RO7: Pizzas,Bakery | RP7: Pizzas,Chinese,Pastas,Beverages | RQ7: Pizzas,Fast Food | RR7: Pizzas,Fast Food,Desserts | RS7: Pizzas,Fast Food,Snacks | RT7: Pizzas,Italian | RU7: Pizzas,Italian,Fast Food,Desserts,Continental,Mediterranean,American,Mexican,Indian,Combo,Beverages,Bakery,French,Sweets,European,Lebanese,Snacks | RV7: Pizzas,Italian,Pastas,Salads | RW7: Pizzas,Italian-American | RX7: Pizzas,Kebabs,North Indian,Fast Food,Desserts | RY7: Pizzas,North Indian | RZ7: Pizzas,North Indian,Fast Food | SA7: Pizzas,Pastas,Beverages | SB7: Pizzas,Pastas,Beverages,Snacks | SC7: Pizzas,Pastas,Italian,Snacks,Continental,Desserts,American,Salads | SD7: Pizzas,Salads,Pastas,Italian,Healthy Food | SE7: Popular Brand Store | SF7: Portuguese | SG7: Punjab | SH7: Punjabi | SI7: Punjabi,North Indian | SJ7: Punjabi,Tandoor,Chinese,Thai,Mughlai | SK7: Rajasthani | SL7: Rajasthani,Indian,Bengali | SM7: Raw meats | SN7: Rayalaseema | SO7: Salads | SP7: Seafood | SQ7: Seafood,Malwani,Indian | SR7: Seafood,North Indian,Chinese,Tandoor,Thai | SS7: Sindhi | ST7: Sindhi,North Indian,Snacks | SU7: Singaporean | SV7: Snacks | SW7: Snacks,Beverages | SX7: Snacks,Beverages,Indian | SY7: Snacks,Chinese | SZ7: Snacks,Combo | TA7: Snacks,Desserts,Beverages | TB7: Snacks,Desserts,Beverages,Pastas | TC7: Snacks,Desserts,Sweets,Chaat | TD7: Snacks,Fast Food | TE7: Snacks,Fast Food,Beverages | TF7: Snacks,Fast Food,Desserts,Beverages | TG7: Snacks,Indian | TH7: Snacks,Indian,Chinese | TI7: Snacks,Mexican,Pizzas,Italian | TJ7: Snacks,Mughlai | TK7: Snacks,Pizzas | TL7: Snacks,Salads,Desserts | TM7: Snacks,South Indian | TN7: Snacks,South Indian,Chaat,Chinese,Indian,Tandoor | TO7: Snacks,South Indian,Telangana | TP7: Snacks,Street Food,Fast Food,Sweets | TQ7: Snacks,Sweets | TR7: South American | TS7: South Indian | TT7: South Indian,Beverages | TU7: South Indian,Biryani | TV7: South Indian,Chaat,Sweets | TW7: South Indian,Chinese | TX7: South Indian,Chinese,Biryani | TY7: South Indian,Chinese,Fast Food,Continental,North Indian,Biryani,Mughlai,Snacks | TZ7: South Indian,Chinese,Fast Food,Desserts,Beverages | UA7: South Indian,Chinese,Indian | UB7: South Indian,Combo,Sweets | UC7: South Indian,Continental,Beverages,Ice Cream | UD7: South Indian,Continental,Snacks | UE7: South Indian,Fast Food,Chinese,Snacks,Juices | UF7: South Indian,Indian,Chinese,Combo | UG7: South Indian,Indian,Chinese,Combo,Punjabi,Biryani | UH7: South Indian,Juices,Indian | UI7: South Indian,North Indian | UJ7: South Indian,North Indian,Andhra | UK7: South Indian,North Indian,Chinese | UL7: South Indian,North Indian,Mughlai | UM7: South Indian,Snacks,Beverages | UN7: South Indian,Snacks,Combo | UO7: Spanish | UP7: Special Discount from (The Scoop) | UQ7: Steakhouse | UR7: Street Food | US7: Street Food,Indian,Beverages | UT7: Street Food,Juices,South Indian | UU7: Street Food,North Indian | UV7: Street Food,North Indian,Chinese,South Indian | UW7: Street Food,South Indian | UX7: Sushi | UY7: SVANidhi Street Food Vendor | UZ7: Sweets | VA7: Sweets,Chaat,Fast Food,Snacks | VB7: Sweets,Desserts | VC7: Sweets,Desserts,Bakery,Beverages | VD7: Sweets,Desserts,Beverages | VE7: Sweets,Desserts,Chaat | VF7: Sweets,Desserts,Chaat,Snacks,Bakery | VG7: Sweets,Desserts,Snacks | VH7: Sweets,Desserts,Snacks,Home Food,Indian | VI7: Sweets,Fast Food | VJ7: Sweets,Indian | VK7: Sweets,Indian,Snacks,Desserts | VL7: Sweets,North Indian,Chinese,South Indian | VM7: Sweets,Snacks | VN7: Sweets,Snacks,Bengali | VO7: Sweets,Snacks,Chaat | VP7: Sweets,Snacks,Fast Food,Indian | VQ7: Sweets,South Indian,North Indian,Snacks | VR7: Tandoor | VS7: Tandoor,Arabian,Grill,Lucknowi,Chinese,Indian,Beverages,Mughlai,Awadhi,Lebanese | VT7: Tandoor,Indian | VU7: Tandoor,Mughlai,Indian,Biryani,North Indian | VV7: Telangana | VW7: Tex-Mex | VX7: Thai | VY7: Thalis | VZ7: Tibetan | WA7: Tibetan,Chinese,Asian,Snacks,Continental,Desserts,Beverages | WB7: Tribal | WC7: Turkish | WD7: Use code XPRESS121 to avail. | WE7: Vietnamese | WF7: Waffle | WG7: Grand Total
A8: Bangalore | B8: Chinese | E8: Ahmedabad | F8: 3 | H8: 19 | W8: 5 | AA8: 11 | AM8: 35 | BM8: 3 | BN8: 5 | BT8: 153 | CM8: 49 | DF8: 1 | DG8: 2 | DH8: 1 | DI8: 10 | DM8: 7 | DS8: 180 | FZ8: 60 | GB8: 72 | GV8: 114 | HR8: 1 | HS8: 184 | JA8: 1 | JB8: 1 | JC8: 27 | JE8: 15 | JR8: 1 | JU8: 5 | JW8: 28 | JX8: 1 | KG8: 206 | MJ8: 49 | MW8: 5 | MY8: 8 | NB8: 11 | NK8: 6 | NN8: 1 | NQ8: 3 | NT8: 2 | NU8: 1 | NX8: 1 | NZ8: 3 | OA8: 22 | OD8: 2 | OE8: 1 | OF8: 25 | OQ8: 1 | OT8: 154 | RB8: 1 | RC8: 5 | RH8: 5 | RK8: 22 | RM8: 1 | RN8: 90 | SH8: 49 | SK8: 2 | SO8: 13 | SP8: 9 | SV8: 110 | TS8: 44 | UR8: 27 | UX8: 1 | UY8: 1 | UZ8: 13 | VR8: 22 | VX8: 10 | VY8: 38 | VZ8: 2 | WG8: 1960
A9: Bangalore | B9: North Indian | E9: Bangalore | F9: 2 | G9: 1 | H9: 52 | V9: 31 | W9: 18 | AA9: 43 | AJ9: 1 | AL9: 4 | AM9: 57 | BM9: 2 | BN9: 17 | BT9: 243 | CM9: 144 | DG9: 4 | DH9: 2 | DI9: 9 | DM9: 41 | DR9: 10 | DS9: 253 | FX9: 8 | FZ9: 82 | GB9: 101 | GV9: 273 | HR9: 14 | HS9: 162 | IW9: 6 | IY9: 2 | JA9: 1 | JB9: 7 | JC9: 2 | JE9: 46 | JR9: 16 | JU9: 24 | JW9: 69 | KG9: 159 | MI9: 1 | MJ9: 76 | MW9: 4 | MY9: 14 | MZ9: 6 | NB9: 31 | NJ9: 2 | NK9: 36 | NL9: 14 | NM9: 8 | NP9: 1 | NQ9: 8 | NT9: 10 | NU9: 10 | NV9: 5 | NX9: 10 | NZ9: 11 | OA9: 26 | OD9: 5 | OF9: 50 | OP9: 2 | OR9: 2 | OT9: 265 | RC9: 12 | RD9: 2 | RE9: 2 | RH9: 31 | RJ9: 2 | RK9: 30 | RM9: 3 | RN9: 66 | SF9: 1 | SG9: 1 | SH9: 40 | SK9: 9 | SO9: 33 | SP9: 64 | SU9: 3 | SV9: 122 | TS9: 154 | UQ9: 3 | UR9: 30 | UX9: 3 | UZ9: 38 | VR9: 40 | VW9: 1 | VX9: 28 | VY9: 26 | VZ9: 11 | WC9: 2 | WE9: 4 | WG9: 3264
A10: Bangalore | B10: Punjabi | E10: Chennai | F10: 3 | G10: 1 | H10: 36 | V10: 14 | W10: 54 | AA10: 30 | AK10: 1 | AL10: 1 | AM10: 71 | BM10: 13 | BN10: 5 | BT10: 223 | CM10: 188 | DH10: 7 | DI10: 11 | DM10: 42 | DR10: 26 | DS10: 313 | FX10: 1 | FZ10: 45 | GB10: 105 | GV10: 181 | HR10: 7 | HS10: 155 | IW10: 2 | JA10: 3 | JB10: 30 | JC10: 1 | JE10: 26 | JR10: 9 | JU10: 12 | JW10: 69 | JX10: 1 | KG10: 227 | MI10: 2 | MJ10: 89 | MW10: 5 | MY10: 3 | MZ10: 6 | NB10: 56 | NJ10: 1 | NK10: 34 | NL10: 10 | NM10: 3 | NP10: 2 | NQ10: 8 | NT10: 8 | NU10: 3 | NV10: 5 | NX10: 2 | NZ10: 8 | OA10: 21 | OE10: 2 | OF10: 21 | OP10: 1 | OS10: 1 | OT10: 218 | RC10: 7 | RE10: 1 | RH10: 12 | RJ10: 1 | RK10: 23 | RM10: 1 | RN10: 64 | SG10: 1 | SH10: 18 | SK10: 2 | SO10: 18 | SP10: 24 | SS10: 1 | SU10: 3 | SV10: 149 | TS10: 222 | UO10: 1 | UR10: 30 | UZ10: 43 | VR10: 60 | VX10: 21 | VY10: 10 | VZ10: 3 | WC10: 1 | WF10: 1 | WG10: 3139
A11: Bangalore | B11: Tandoor | E11: Delhi | F11: 2 | G11: 1 | H11: 24 | V11: 4 | W11: 2 | AA11: 18 | AL11: 1 | AM11: 34 | BM11: 1 | BN11: 2 | BT11: 130 | CM11: 69 | DH11: 3 | DI11: 1 | DM11: 4 | DR11: 1 | DS11: 224 | FZ11: 42 | GB11: 52 | GV11: 108 | HR11: 1 | HS11: 126 | IW11: 1 | JB11: 1 | JC11: 1 | JE11: 23 | JR11: 10 | JU11: 8 | JW11: 25 | KG11: 147 | MJ11: 58 | MW11: 1 | MY11: 2 | MZ11: 5 | NB11: 6 | NJ11: 1 | NK11: 21 | NL11: 1 | NM11: 2 | NQ11: 2 | NT11: 7 | NU11: 4 | NX11: 1 | NZ11: 1 | OA11: 9 | OF11: 52 | OQ11: 1 | OS11: 1 | OT11: 215 | RC11: 4 | RE11: 2 | RH11: 10 | RJ11: 1 | RK11: 17 | RM11: 1 | RN11: 41 | SE11: 1 | SF11: 1 | SH11: 35 | SK11: 1 | SO11: 15 | SP11: 9 | SV11: 106 | TS11: 27 | UQ11: 1 | UR11: 17 | UX11: 3 | UZ11: 17 | VR11: 49 | VX11: 13 | VY11: 23 | VZ11: 8 | WF11: 1 | WG11: 1859
A12: Bangalore | B12: Chinese | E12: Hyderabad | F12: 2 | H12: 29 | O12: 1 | T12: 1 | V12: 15 | W12: 51 | X12: 1 | Y12: 1 | Z12: 1 | AA12: 10 | AL12: 1 | AM12: 52 | AN12: 1 | AP12: 1 | AR12: 7 | AS12: 1 | AU12: 1 | AV12: 1 | AW12: 1 | AX12: 1 | AY12: 1 | BB12: 1 | BD12: 1 | BF12: 1 | BG12: 1 | BH12: 1 | BI12: 1 | BK12: 1 | BM12: 1 | BN12: 3 | BT12: 155 | BU12: 1 | BV12: 2 | BY12: 2 | CB12: 1 | CE12: 1 | CF12: 1 | CI12: 1 | CJ12: 1 | CK12: 1 | CM12: 167 | CO12: 1 | CS12: 1 | DB12: 2 | DC12: 1 | DD12: 1 | DF12: 1 | DI12: 2 | DJ12: 1 | DM12: 21 | DN12: 1 | DO12: 1 | DP12: 1 | DQ12: 1 | DS12: 268 | EJ12: 1 | EM12: 1 | EQ12: 1 | ER12: 1 | EW12: 1 | FM12: 1 | FY12: 1 | FZ12: 21 | GB12: 39 | GT12: 1 | GU12: 1 | GV12: 141 | GW12: 4 | GZ12: 1 | HC12: 4 | HE12: 1 | HH12: 1 | HI12: 1 | HK12: 1 | HL12: 1 | HQ12: 1 | HR12: 4 | HS12: 132 | HT12: 1 | HU12: 2 | HZ12: 1 | ID12: 1 | IJ12: 1 | IN12: 1 | IR12: 1 | IW12: 1 | JB12: 4 | JD12: 7 | JE12: 19 | JF12: 1 | JH12: 1 | JJ12: 1 | JL12: 1 | JN12: 1 | JQ12: 1 | JR12: 5 | JU12: 22 | JW12: 53 | JX12: 1 | JZ12: 1 | KA12: 1 | KB12: 5 | KD12: 2 | KE12: 1 | KG12: 148 | KI12: 1 | KL12: 3 | KM12: 1 | LG12: 1 | LK12: 1 | LL12: 1 | LM12: 1 | MB12: 1 | MD12: 2 | ME12: 1 | MJ12: 50 | ML12: 1 | MM12: 2 | MS12: 1 | MW12: 1 | MY12: 4 | MZ12: 1 | NB12: 24 | NC12: 1 | ND12: 1 | NG12: 1 | NH12: 1 | NJ12: 1 | NK12: 30 | NL12: 3 | NN12: 1 | NQ12: 15 | NT12: 4 | NU12: 6 | NX12: 1 | NZ12: 2 | OA12: 7 | OC12: 1 | OE12: 1 | OF12: 36 | OT12: 185 | OZ12: 1 | PB12: 1 | PF12: 1 | PH12: 1 | PJ12: 1 | PR12: 1 | PS12: 1 | PU12: 1 | PW12: 1 | PY12: 1 | QH12: 1 | QJ12: 1 | QM12: 1 | QR12: 3 | QS12: 1 | QW12: 1 | QX12: 1 | RC12: 4 | RE12: 3 | RH12: 5 | RJ12: 1 | RK12: 14 | RM12: 1 | RN12: 69 | RO12: 1 | RQ12: 1 | RU12: 1 | RZ12: 1 | SH12: 14 | SI12: 1 | SK12: 1 | SN12: 4 | SO12: 15 | SP12: 17 | SU12: 1 | SV12: 102 | SW12: 1 | SZ12: 1 | TE12: 1 | TG12: 1 | TH12: 1 | TI12: 1 | TM12: 1 | TO12: 1 | TS12: 160 | TT12: 1 | TU12: 1 | TV12: 1 | TW12: 2 | TX12: 1 | TZ12: 1 | UA12: 1 | UB12: 1 | UE12: 1 | UH12: 1 | UI12: 2 | UJ12: 1 | UK12: 2 | UL12: 1 | UN12: 1 | UQ12: 1 | UR12: 13 | US12: 1 | UW12: 1 | UZ12: 47 | VB12: 2 | VC12: 1 | VD12: 1 | VF12: 1 | VH12: 1 | VL12: 1 | VM12: 1 | VN12: 1 | VQ12: 1 | VR12: 62 | VV12: 2 | VX12: 5 | VY12: 6 | VZ12: 2 | WC12: 2 | WF12: 1 | WG12: 2480
A13: Bangalore | B13: Rajasthani | E13: Kolkata | F13: 1 | H13: 39 | J13: 1 | M13: 1 | O13: 1 | P13: 1 | Q13: 1 | R13: 1 | W13: 4 | AA13: 41 | AC13: 1 | AI13: 1 | AL13: 3 | AM13: 46 | AP13: 1 | AR13: 3 | AT13: 1 | AY13: 1 | AZ13: 1 | BA13: 1 | BC13: 3 | BE13: 1 | BI13: 1 | BJ13: 1 | BL13: 5 | BM13: 2 | BN13: 76 | BO13: 1 | BP13: 1 | BQ13: 1 | BR13: 1 | BS13: 1 | BT13: 163 | BX13: 1 | BZ13: 1 | CB13: 1 | CC13: 1 | CG13: 1 | CH13: 1 | CJ13: 2 | CM13: 178 | CQ13: 1 | CT13: 1 | CW13: 1 | CX13: 2 | CY13: 1 | CZ13: 1 | DF13: 1 | DH13: 7 | DI13: 4 | DM13: 7 | DS13: 493 | DT13: 1 | EG13: 2 | EJ13: 5 | EN13: 1 | EP13: 1 | EZ13: 1 | FK13: 1 | FN13: 1 | FX13: 2 | FZ13: 106 | GA13: 1 | GB13: 134 | GC13: 1 | GD13: 1 | GH13: 1 | GI13: 1 | GK13: 1 | GL13: 1 | GM13: 1 | GN13: 1 | GP13: 1 | GQ13: 1 | GR13: 1 | GV13: 152 | GW13: 3 | GY13: 1 | HA13: 1 | HB13: 1 | HC13: 1 | HF13: 1 | HG13: 2 | HI13: 2 | HJ13: 1 | HO13: 1 | HP13: 1 | HR13: 9 | HS13: 180 | HU13: 2 | HV13: 1 | HW13: 1 | HX13: 1 | HY13: 1 | IA13: 1 | IB13: 1 | IC13: 1 | IF13: 1 | IH13: 1 | IM13: 1 | JB13: 2 | JE13: 30 | JI13: 1 | JP13: 1 | JR13: 4 | JS13: 1 | JU13: 1 | JW13: 45 | JY13: 1 | KG13: 348 | KH13: 1 | KL13: 3 | KP13: 1 | KW13: 1 | KZ13: 1 | LA13: 1 | LC13: 1 | LH13: 1 | LJ13: 1 | LK13: 1 | LN13: 1 | LS13: 1 | LT13: 1 | LY13: 1 | MA13: 1 | MI13: 1 | MJ13: 93 | MQ13: 1 | MV13: 1 | MW13: 1 | MY13: 1 | MZ13: 7 | NB13: 10 | NF13: 1 | NG13: 1 | NI13: 1 | NK13: 52 | NL13: 2 | NM13: 1 | NN13: 1 | NP13: 1 | NQ13: 10 | NT13: 4 | NV13: 1 | NZ13: 4 | OA13: 20 | OD13: 4 | OF13: 70 | OH13: 1 | OI13: 1 | OR13: 1 | OS13: 1 | OT13: 212 | OX13: 1 | OY13: 1 | PL13: 1 | PR13: 1 | PT13: 1 | PY13: 1 | QA13: 1 | QB13: 1 | QH13: 1 | QI13: 1 | QU13: 1 | QV13: 1 | QX13: 1 | RC13: 23 | RE13: 1 | RG13: 1 | RH13: 11 | RK13: 37 | RL13: 1 | RN13: 56 | RP13: 1 | RQ13: 1 | RW13: 1 | RY13: 1 | SA13: 2 | SD13: 1 | SH13: 15 | SK13: 2 | SL13: 1 | SO13: 16 | SP13: 33 | SU13: 2 | SV13: 130 | SW13: 1 | SX13: 1 | SY13: 1 | TA13: 1 | TB13: 1 | TC13: 1 | TD13: 1 | TF13: 1 | TG13: 2 | TH13: 1 | TJ13: 1 | TL13: 1 | TP13: 1 | TQ13: 2 | TS13: 67 | TT13: 2 | TY13: 1 | UD13: 1 | UF13: 1 | UK13: 1 | UM13: 1 | UQ13: 2 | UR13: 15 | UV13: 2 | UX13: 1 | UZ13: 21 | VA13: 1 | VB13: 3 | VE13: 1 | VG13: 1 | VI13: 2 | VJ13: 1 | VM13: 3 | VO13: 1 | VP13: 1 | VR13: 88 | VX13: 35 | VY13: 39 | VZ13: 30 | WB13: 2 | WE13: 1 | WF13: 2 | WG13: 3393
A14: Bangalore | B14: Gujarati | E14: Mumbai | F14: 3 | H14: 39 | I14: 1 | K14: 1 | L14: 1 | N14: 1 | O14: 1 | S14: 1 | T14: 1 | U14: 1 | V14: 1 | W14: 6 | AA14: 39 | AB14: 2 | AD14: 1 | AE14: 1 | AF14: 1 | AG14: 1 | AH14: 1 | AM14: 76 | AO14: 1 | AQ14: 1 | AR14: 5 | AT14: 1 | BA14: 1 | BM14: 3 | BN14: 8 | BT14: 137 | BV14: 1 | BW14: 1 | CA14: 1 | CD14: 1 | CJ14: 1 | CL14: 1 | CM14: 120 | CN14: 9 | CP14: 1 | CR14: 1 | CU14: 1 | CV14: 1 | DA14: 1 | DE14: 1 | DG14: 1 | DH14: 4 | DI14: 4 | DK14: 1 | DL14: 1 | DM14: 12 | DR14: 1 | DS14: 364 | DT14: 1 | DU14: 1 | DV14: 1 | DW14: 1 | DX14: 1 | DY14: 1 | DZ14: 1 | EA14: 1 | EB14: 1 | EC14: 1 | ED14: 1 | EE14: 1 | EF14: 1 | EG14: 3 | EH14: 1 | EI14: 1 | EJ14: 2 | EK14: 1 | EL14: 1 | EO14: 1 | ES14: 1 | ET14: 1 | EU14: 1 | EV14: 1 | EW14: 3 | EX14: 1 | EY14: 1 | FA14: 1 | FB14: 1 | FC14: 1 | FD14: 1 | FE14: 2 | FF14: 1 | FG14: 1 | FH14: 1 | FI14: 1 | FJ14: 1 | FK14: 1 | FL14: 1 | FO14: 1 | FP14: 1 | FQ14: 2 | FR14: 1 | FS14: 2 | FT14: 1 | FU14: 1 | FV14: 1 | FW14: 1 | FX14: 1 | FZ14: 58 | GB14: 57 | GE14: 1 | GF14: 1 | GG14: 1 | GJ14: 1 | GO14: 1 | GS14: 1 | GV14: 194 | GW14: 3 | GX14: 1 | GY14: 1 | GZ14: 1 | HC14: 5 | HD14: 1 | HG14: 1 | HI14: 3 | HM14: 1 | HN14: 1 | HR14: 13 | HS14: 177 | IE14: 1 | IG14: 1 | II14: 1 | IK14: 1 | IL14: 1 | IO14: 1 | IP14: 1 | IQ14: 2 | IR14: 1 | IS14: 1 | IT14: 1 | IU14: 1 | IV14: 1 | IW14: 1 | IX14: 1 | IY14: 1 | IZ14: 2 | JB14: 4 | JC14: 4 | JE14: 27 | JG14: 1 | JK14: 1 | JM14: 1 | JO14: 1 | JR14: 12 | JT14: 1 | JU14: 6 | JV14: 1 | JW14: 40 | JZ14: 2 | KB14: 4 | KC14: 1 | KF14: 2 | KG14: 262 | KJ14: 1 | KK14: 1 | KL14: 9 | KN14: 1 | KO14: 1 | KQ14: 1 | KR14: 1 | KS14: 1 | KT14: 1 | KU14: 1 | KV14: 1 | KX14: 1 | KY14: 1 | LB14: 1 | LD14: 1 | LE14: 1 | LF14: 1 | LI14: 1 | LK14: 1 | LO14: 1 | LP14: 1 | LQ14: 1 | LR14: 1 | LU14: 1 | LV14: 1 | LW14: 1 | LX14: 1 | LZ14: 1 | MC14: 1 | MF14: 1 | MG14: 1 | MH14: 1 | MJ14: 59 | MK14: 1 | MN14: 1 | MO14: 1 | MP14: 1 | MR14: 1 | MT14: 1 | MU14: 2 | MW14: 2 | MX14: 1 | MY14: 5 | MZ14: 7 | NA14: 1 | NB14: 24 | NE14: 1 | NF14: 1 | NK14: 31 | NL14: 5 | NM14: 4 | NO14: 2 | NP14: 2 | NQ14: 22 | NR14: 1 | NS14: 1 | NT14: 4 | NU14: 13 | NV14: 1 | NW14: 5 | NX14: 3 | NY14: 1 | NZ14: 8 | OA14: 19 | OB14: 1 | OD14: 2 | OE14: 1 | OF14: 73 | OG14: 1 | OJ14: 1 | OK14: 2 | OL14: 2 | OM14: 1 | ON14: 1 | OO14: 1 | OS14: 3 | OT14: 207 | OU14: 1 | OV14: 1 | OW14: 1 | OX14: 5 | PA14: 1 | PC14: 1 | PD14: 1 | PE14: 1 | PG14: 1 | PI14: 1 | PJ14: 1 | PK14: 1 | PM14: 1 | PN14: 1 | PO14: 1 | PP14: 1 | PQ14: 3 | PT14: 1 | PV14: 1 | PX14: 1 | PZ14: 1 | QC14: 1 | QD14: 1 | QE14: 1 | QF14: 1 | QG14: 1 | QK14: 1 | QL14: 3 | QN14: 1 | QO14: 1 | QP14: 1 | QQ14: 1 | QT14: 1 | QY14: 1 | QZ14: 1 | RA14: 1 | RC14: 8 | RE14: 1 | RF14: 1 | RH14: 14 | RI14: 1 | RJ14: 2 | RK14: 22 | RM14: 1 | RN14: 68 | RQ14: 1 | RR14: 1 | RS14: 1 | RT14: 1 | RV14: 1 | RX14: 1 | SB14: 1 | SC14: 1 | SF14: 1 | SH14: 26 | SI14: 1 | SJ14: 1 | SK14: 3 | SM14: 1 | SO14: 19 | SP14: 45 | SQ14: 1 | SR14: 1 | SS14: 2 | ST14: 1 | SV14: 112 | TG14: 1 | TK14: 1 | TN14: 1 | TQ14: 1 | TS14: 75 | UC14: 1 | UG14: 1 | UO14: 1 | UP14: 1 | UR14: 19 | UT14: 1 | UU14: 1 | UX14: 4 | UZ14: 33 | VK14: 1 | VR14: 64 | VS14: 1 | VT14: 1 | VU14: 1 | VX14: 22 | VY14: 17 | VZ14: 12 | WA14: 1 | WC14: 4 | WE14: 1 | WG14: 3051
A15: Bangalore | B15: North Indian | E15: Pune | F15: 3 | H15: 47 | V15: 3 | W15: 10 | AA15: 28 | AM15: 65 | BM15: 1 | BN15: 4 | BT15: 220 | CM15: 125 | DG15: 3 | DH15: 1 | DI15: 10 | DM15: 9 | DR15: 1 | DS15: 336 | FZ15: 58 | GB15: 101 | GV15: 176 | HR15: 15 | HS15: 276 | IW15: 2 | IY15: 1 | JB15: 1 | JC15: 4 | JE15: 25 | JR15: 3 | JU15: 9 | JW15: 60 | JX15: 1 | KG15: 184 | MI15: 1 | MJ15: 79 | MW15: 4 | MY15: 3 | MZ15: 5 | NB15: 14 | NK15: 24 | NL15: 3 | NM15: 3 | NO15: 1 | NP15: 1 | NQ15: 10 | NT15: 3 | NU15: 63 | NV15: 3 | NW15: 5 | NX15: 4 | NZ15: 7 | OA15: 18 | OD15: 4 | OF15: 64 | OR15: 3 | OT15: 334 | RC15: 9 | RE15: 2 | RH15: 9 | RJ15: 2 | RK15: 24 | RM15: 2 | RN15: 69 | SH15: 41 | SK15: 6 | SM15: 1 | SO15: 17 | SP15: 42 | SV15: 114 | TR15: 1 | TS15: 79 | UR15: 33 | UX15: 2 | UZ15: 17 | VR15: 26 | VX15: 20 | VY15: 26 | VZ15: 10 | WC15: 1 | WD15: 1 | WE15: 1 | WG15: 2993
A16: Bangalore | B16: Snacks | E16: Surat | F16: 1 | H16: 12 | AA16: 7 | AK16: 1 | AM16: 14 | BM16: 3 | BT16: 100 | CM16: 39 | DH16: 3 | DI16: 3 | DM16: 9 | DS16: 157 | FZ16: 37 | GB16: 25 | GV16: 97 | HS16: 158 | JC16: 32 | JE16: 7 | JR16: 12 | JU16: 3 | JW16: 30 | KG16: 94 | MJ16: 40 | MW16: 2 | MY16: 2 | NB16: 13 | NK16: 4 | NQ16: 4 | NT16: 1 | OA16: 11 | OF16: 29 | OT16: 131 | RC16: 3 | RE16: 2 | RH16: 8 | RK16: 15 | RM16: 1 | RN16: 64 | SH16: 79 | SK16: 17 | SO16: 5 | SP16: 11 | SU16: 1 | SV16: 68 | TS16: 29 | UR16: 14 | UX16: 1 | UZ16: 20 | VR16: 16 | VX16: 5 | VY16: 43 | WF16: 1 | WG16: 1484
A17: Bangalore | B17: Desserts | E17: Grand Total | F17: 20 | G17: 3 | H17: 297 | I17: 1 | J17: 1 | K17: 1 | L17: 1 | M17: 1 | N17: 1 | O17: 3 | P17: 1 | Q17: 1 | R17: 1 | S17: 1 | T17: 2 | U17: 1 | V17: 68 | W17: 150 | X17: 1 | Y17: 1 | Z17: 1 | AA17: 227 | AB17: 2 | AC17: 1 | AD17: 1 | AE17: 1 | AF17: 1 | AG17: 1 | AH17: 1 | AI17: 1 | AJ17: 1 | AK17: 2 | AL17: 10 | AM17: 450 | AN17: 1 | AO17: 1 | AP17: 2 | AQ17: 1 | AR17: 15 | AS17: 1 | AT17: 2 | AU17: 1 | AV17: 1 | AW17: 1 | AX17: 1 | AY17: 2 | AZ17: 1 | BA17: 2 | BB17: 1 | BC17: 3 | BD17: 1 | BE17: 1 | BF17: 1 | BG17: 1 | BH17: 1 | BI17: 2 | BJ17: 1 | BK17: 1 | BL17: 5 | BM17: 29 | BN17: 120 | BO17: 1 | BP17: 1 | BQ17: 1 | BR17: 1 | BS17: 1 | BT17: 1524 | BU17: 1 | BV17: 3 | BW17: 1 | BX17: 1 | BY17: 2 | BZ17: 1 | CA17: 1 | CB17: 2 | CC17: 1 | CD17: 1 | CE17: 1 | CF17: 1 | CG17: 1 | CH17: 1 | CI17: 1 | CJ17: 4 | CK17: 1 | CL17: 1 | CM17: 1079 | CN17: 9 | CO17: 1 | CP17: 1 | CQ17: 1 | CR17: 1 | CS17: 1 | CT17: 1 | CU17: 1 | CV17: 1 | CW17: 1 | CX17: 2 | CY17: 1 | CZ17: 1 | DA17: 1 | DB17: 2 | DC17: 1 | DD17: 1 | DE17: 1 | DF17: 3 | DG17: 10 | DH17: 28 | DI17: 54 | DJ17: 1 | DK17: 1 | DL17: 1 | DM17: 152 | DN17: 1 | DO17: 1 | DP17: 1 | DQ17: 1 | DR17: 39 | DS17: 2588 | DT17: 2 | DU17: 1 | DV17: 1 | DW17: 1 | DX17: 1 | DY17: 1 | DZ17: 1 | EA17: 1 | EB17: 1 | EC17: 1 | ED17: 1 | EE17: 1 | EF17: 1 | EG17: 5 | EH17: 1 | EI17: 1 | EJ17: 8 | EK17: 1 | EL17: 1 | EM17: 1 | EN17: 1 | EO17: 1 | EP17: 1 | EQ17: 1 | ER17: 1 | ES17: 1 | ET17: 1 | EU17: 1 | EV17: 1 | EW17: 4 | EX17: 1 | EY17: 1 | EZ17: 1 | FA17: 1 | FB17: 1 | FC17: 1 | FD17: 1 | FE17: 2 | FF17: 1 | FG17: 1 | FH17: 1 | FI17: 1 | FJ17: 1 | FK17: 2 | FL17: 1 | FM17: 1 | FN17: 1 | FO17: 1 | FP17: 1 | FQ17: 2 | FR17: 1 | FS17: 2 | FT17: 1 | FU17: 1 | FV17: 1 | FW17: 1 | FX17: 12 | FY17: 1 | FZ17: 509 | GA17: 1 | GB17: 686 | GC17: 1 | GD17: 1 | GE17: 1 | GF17: 1 | GG17: 1 | GH17: 1 | GI17: 1 | GJ17: 1 | GK17: 1 | GL17: 1 | GM17: 1 | GN17: 1 | GO17: 1 | GP17: 1 | GQ17: 1 | GR17: 1 | GS17: 1 | GT17: 1 | GU17: 1 | GV17: 1436 | GW17: 10 | GX17: 1 | GY17: 2 | GZ17: 2 | HA17: 1 | HB17: 1 | HC17: 10 | HD17: 1 | HE17: 1 | HF17: 1 | HG17: 3 | HH17: 1 | HI17: 6 | HJ17: 1 | HK17: 1 | HL17: 1 | HM17: 1 | HN17: 1 | HO17: 1 | HP17: 1 | HQ17: 1 | HR17: 64 | HS17: 1550 | HT17: 1 | HU17: 4 | HV17: 1 | HW17: 1 | HX17: 1 | HY17: 1 | HZ17: 1 | IA17: 1 | IB17: 1 | IC17: 1 | ID17: 1 | IE17: 1 | IF17: 1 | IG17: 1 | IH17: 1 | II17: 1 | IJ17: 1 | IK17: 1 | IL17: 1 | IM17: 1 | IN17: 1 | IO17: 1 | IP17: 1 | IQ17: 2 | IR17: 2 | IS17: 1 | IT17: 1 | IU17: 1 | IV17: 1 | IW17: 13 | IX17: 1 | IY17: 4 | IZ17: 2 | JA17: 5 | JB17: 50 | JC17: 71 | JD17: 7 | JE17: 218 | JF17: 1 | JG17: 1 | JH17: 1 | JI17: 1 | JJ17: 1 | JK17: 1 | JL17: 1 | JM17: 1 | JN17: 1 | JO17: 1 | JP17: 1 | JQ17: 1 | JR17: 72 | JS17: 1 | JT17: 1 | JU17: 90 | JV17: 1 | JW17: 419 | JX17: 4 | JY17: 1 | JZ17: 3 | KA17: 1 | KB17: 9 | KC17: 1 | KD17: 2 | KE17: 1 | KF17: 2 | KG17: 1775 | KH17: 1 | KI17: 1 | KJ17: 1 | KK17: 1 | KL17: 15 | KM17: 1 | KN17: 1 | KO17: 1 | KP17: 1 | KQ17: 1 | KR17: 1 | KS17: 1 | KT17: 1 | KU17: 1 | KV17: 1 | KW17: 1 | KX17: 1 | KY17: 1 | KZ17: 1 | LA17: 1 | LB17: 1 | LC17: 1 | LD17: 1 | LE17: 1 | LF17: 1 | LG17: 1 | LH17: 1 | LI17: 1 | LJ17: 1 | LK17: 3 | LL17: 1 | LM17: 1 | LN17: 1 | LO17: 1 | LP17: 1 | LQ17: 1 | LR17: 1 | LS17: 1 | LT17: 1 | LU17: 1 | LV17: 1 | LW17: 1 | LX17: 1 | LY17: 1 | LZ17: 1 | MA17: 1 | MB17: 1 | MC17: 1 | MD17: 2 | ME17: 1 | MF17: 1 | MG17: 1 | MH17: 1 | MI17: 5 | MJ17: 593 | MK17: 1 | ML17: 1 | MM17: 2 | MN17: 1 | MO17: 1 | MP17: 1 | MQ17: 1 | MR17: 1 | MS17: 1 | MT17: 1 | MU17: 2 | MV17: 1 | MW17: 25 | MX17: 1 | MY17: 42 | MZ17: 37 | NA17: 1 | NB17: 189 | NC17: 1 | ND17: 1 | NE17: 1 | NF17: 2 | NG17: 2 | NH17: 1 | NI17: 1 | NJ17: 5 | NK17: 238 | NL17: 38 | NM17: 21 | NN17: 3 | NO17: 3 | NP17: 7 | NQ17: 82 | NR17: 1 | NS17: 1 | NT17: 43 | NU17: 100 | NV17: 15 | NW17: 10 | NX17: 22 | NY17: 1 | NZ17: 44 | OA17: 153 | OB17: 1 | OC17: 1 | OD17: 17 | OE17: 5 | OF17: 420 | OG17: 1 | OH17: 1 | OI17: 1 | OJ17: 1 | OK17: 2 | OL17: 2 | OM17: 1 | ON17: 1 | OO17: 1 | OP17: 3 | OQ17: 2 | OR17: 6 | OS17: 6 | OT17: 1921 | OU17: 1 | OV17: 1 | OW17: 1 | OX17: 6 | OY17: 1 | OZ17: 1 | PA17: 1 | PB17: 1 | PC17: 1 | PD17: 1 | PE17: 1 | PF17: 1 | PG17: 1 | PH17: 1 | PI17: 1 | PJ17: 2 | PK17: 1 | PL17: 1 | PM17: 1 | PN17: 1 | PO17: 1 | PP17: 1 | PQ17: 3 | PR17: 2 | PS17: 1 | PT17: 2 | PU17: 1 | PV17: 1 | PW17: 1 | PX17: 1 | PY17: 2 | PZ17: 1 | QA17: 1 | QB17: 1 | QC17: 1 | QD17: 1 | QE17: 1 | QF17: 1 | QG17: 1 | QH17: 2 | QI17: 1 | QJ17: 1 | QK17: 1 | QL17: 3 | QM17: 1 | QN17: 1 | QO17: 1 | QP17: 1 | QQ17: 1 | QR17: 3 | QS17: 1 | QT17: 1 | QU17: 1 | QV17: 1 | QW17: 1 | QX17: 2 | QY17: 1 | QZ17: 1 | RA17: 1 | RB17: 1 | RC17: 75 | RD17: 2 | RE17: 14 | RF17: 1 | RG17: 1 | RH17: 105 | RI17: 1 | RJ17: 9 | RK17: 204 | RL17: 1 | RM17: 11 | RN17: 587 | RO17: 1 | RP17: 1 | RQ17: 3 | RR17: 1 | RS17: 1 | RT17: 1 | RU17: 1 | RV17: 1 | RW17: 1 | RX17: 1 | RY17: 1 | RZ17: 1 | SA17: 2 | SB17: 1 | SC17: 1 | SD17: 1 | SE17: 1 | SF17: 3 | SG17: 2 | SH17: 317 | SI17: 2 | SJ17: 1 | SK17: 43 | SL17: 1 | SM17: 2 | SN17: 4 | SO17: 151 | SP17: 254 | SQ17: 1 | SR17: 1 | SS17: 3 | ST17: 1 | SU17: 10 | SV17: 1013 | SW17: 2 | SX17: 1 | SY17: 1 | SZ17: 1 | TA17: 1 | TB17: 1 | TC17: 1 | TD17: 1 | TE17: 1 | TF17: 1 | TG17: 4 | TH17: 2 | TI17: 1 | TJ17: 1 | TK17: 1 | TL17: 1 | TM17: 1 | TN17: 1 | TO17: 1 | TP17: 1 | TQ17: 3 | TR17: 1 | TS17: 857 | TT17: 3 | TU17: 1 | TV17: 1 | TW17: 2 | TX17: 1 | TY17: 1 | TZ17: 1 | UA17: 1 | UB17: 1 | UC17: 1 | UD17: 1 | UE17: 1 | UF17: 1 | UG17: 1 | UH17: 1 | UI17: 2 | UJ17: 1 | UK17: 3 | UL17: 1 | UM17: 1 | UN17: 1 | UO17: 2 | UP17: 1 | UQ17: 7 | UR17: 198 | US17: 1 | UT17: 1 | UU17: 1 | UV17: 2 | UW17: 1 | UX17: 15 | UY17: 1 | UZ17: 249 | VA17: 1 | VB17: 5 | VC17: 1 | VD17: 1 | VE17: 1 | VF17: 1 | VG17: 1 | VH17: 1 | VI17: 2 | VJ17: 1 | VK17: 1 | VL17: 1 | VM17: 4 | VN17: 1 | VO17: 1 | VP17: 1 | VQ17: 1 | VR17: 427 | VS17: 1 | VT17: 1 | VU17: 1 | VV17: 2 | VW17: 1 | VX17: 159 | VY17: 228 | VZ17: 78 | WA17: 1 | WB17: 2 | WC17: 10 | WD17: 1 | WE17: 7 | WF17: 6 | WG17: 23623
A18: Bangalore | B18: Beverages
A19: Bangalore | B19: Thalis
A20: Bangalore | B20: Chaat
A21: Bangalore | B21: Mughlai
A22: Bangalore | B22: North Indian
A23: Bangalore | B23: Mexican
A24: Bangalore | B24: Beverages
A25: Bangalore | B25: Salads
A26: Bangalore | B26: Desserts
A27: Bangalore | B27: British
A28: Bangalore | B28: Bakery
A29: Bangalore | B29: Pizzas
... A23624: Ahmedabad | B23624: Chinese

Sheet swiggy PROJECT DATASET
A1: ID | B1: Area | C1: City | D1: Restaurant | E1: Price | F1: Avg ratings | G1: Total ratings | H1: Food type | I1: Address | J1: Delivery time
A2: 211 | B2: Koramangala | C2: Bangalore | D2: Tandoor Hut | E2: 300 | F2: 4.4 | G2: 100 | H2: Biryani,Chinese,North Indian,South Indian | I2: 5Th Block | J2: 59
A3: 221 | B3: Koramangala | C3: Bangalore | D3: Tunday Kababi | E3: 300 | F3: 4.1 | G3: 100 | H3: Mughlai,Lucknowi | I3: 5Th Block | J3: 56
A4: 246 | B4: Jogupalya | C4: Bangalore | D4: Kim Lee | E4: 650 | F4: 4.4 | G4: 100 | H4: Chinese | I4: Double Road | J4: 50
A5: 248 | B5: Indiranagar | C5: Bangalore | D5: New Punjabi Hotel | E5: 250 | F5: 3.9 | G5: 500 | H5: North Indian,Punjabi,Tandoor,Chinese | I5: 80 Feet Road | J5: 57
A6: 249 | B6: Indiranagar | C6: Bangalore | D6: Nh8 | E6: 350 | F6: 4 | G6: 50 | H6: Rajasthani,Gujarati,North Indian,Snacks,Desserts,Beverages,Thalis,Chaat | I6: 80 Feet Road | J6: 63
A7: 254 | B7: Indiranagar | C7: Bangalore | D7: Treat | E7: 800 | F7: 4.5 | G7: 100 | H7: Mughlai,North Indian | I7: 100 Feet Road | J7: 56
A8: 258 | B8: Indiranagar | C8: Bangalore | D8: Chinita Real Mexican Food | E8: 1000 | F8: 4.5 | G8: 500 | H8: Mexican,Beverages,Salads | I8: Double Road | J8: 53
A9: 263 | B9: Koramangala | C9: Bangalore | D9: Cupcake Noggins - Cakespastries And Desserts | E9: 150 | F9: 4.3 | G9: 100 | H9: Desserts,British,Bakery,Pizzas,Snacks | I9: 4Th Block | J9: 57
A10: 267 | B10: Domlur | C10: Bangalore | D10: Tea Brew | E10: 350 | F10: 4.1 | G10: 100 | H10: American,Italian,Beverages,Continental,Chinese,Pastas,Pizzas,Fast Food | I10: Double Road | J10: 57
A11: 308 | B11: Koramangala | C11: Bangalore | D11: Bangaliana | E11: 300 | F11: 4 | G11: 500 | H11: Bengali | I11: 7Th Block | J11: 57
A12: 435 | B12: Koramangala | C12: Bangalore | D12: Bamey'S Restro Cafe | E12: 400 | F12: 4.4 | G12: 100 | H12: Chinese,Thai,Nepalese | I12: 5Th Block | J12: 56
A13: 446 | B13: Cooke Town | C13: Bangalore | D13: Altaf'S Chillies Restaurants | E13: 250 | F13: 4.3 | G13: 500 | H13: North Indian,Chinese | I13: Cooke Town | J13: 55
... A2983: 298694 | B2983: Camp | C2983: Pune | D2983: Ibaco | E2983: 800 | F2983: 2.9 | G2983: 80 | H2983: Ice Cream,Desserts | I2983: Camp | J2983: 35
A2984: 299150 | B2984: 26 | C2984: Chennai | D2984: Malabar Point | E2984: 450 | F2984: 4.2 | G2984: 100 | H2984: Biryani,Kerala,South Indian,Thalis | I2984: Alwarpet (Malabar Point) | J2984: 58
A2985: 299226 | B2985: Powai | C2985: Mumbai | D2985: Pratik Restaurant | E2985: 250 | F2985: 4.5 | G2985: 20 | H2985: Indian Chinese Tandoor Punjabi | I2985: Powai | J2985: 54
A2986: 299311 | B2986: Jamalia | C2986: Chennai | D2986: Waffle Dreams | E2986: 200 | F2986: 2.9 | G2986: 80 | H2986: Beverages,Desserts,Snacks | I2986: Perambur | J2986: 52
A2987: 299312 | B2987: Rohini | C2987: Delhi | D2987: Meals And Bowls | E2987: 300 | F2987: 4 | G2987: 20 | H2987: North Indian,Punjabi,Mughlai,Home Food | I2987: Rohini | J2987: 36
A2988: 299369 | B2988: Sec-9 Rohini | C2988: Delhi | D2988: Home Factory | E2988: 200 | F2988: 2.9 | G2988: 80 | H2988: North Indian,Continental,Chinese | I2988: Rohini | J2988: 50
A2989: 299435 | B2989: Perambur | C2989: Chennai | D2989: Arabian Express | E2989: 300 | F2989: 4.4 | G2989: 20 | H2989: Indian,Arabian | I2989: Perambur | J2989: 65
A2990: 299501 | B2990: Machuabazar | C2990: Kolkata | D2990: Vanakkam | E2990: 300 | F2990: 4.4 | G2990: 50 | H2990: South Indian,Ice Cream | I2990: Maniktala | J2990: 49
A2991: 299656 | B2991: Bidhannagar | C2991: Kolkata | D2991: Hatari | E2991: 500 | F2991: 4.5 | G2991: 500 | H2991: Chinese,Indian | I2991: Salt Lake | J2991: 73
A2992: 299680 | B2992: Kothrud | C2992: Pune | D2992: Box.72 | E2992: 200 | F2992: 2.9 | G2992: 80 | H2992: Fast Food,Chinese,Indian | I2992: Kothrud | J2992: 49
A2993: 299750 | B2993: Alwarpet | C2993: Chennai | D2993: Dakshin At Crowne Plaza Chennai | E2993: 300 | F2993: 4.5 | G2993: 20 | H2993: North Indian,Indian,Salads,Biryani,Chinese,Juices,Desserts | I2993: Austin Nagar | J2993: 69
A2994: 299751 | B2994: Alwarpet | C2994: Chennai | D2994: Cappuccino At Crowne Plaza Chennai | E2994: 300 | F2994: 4.5 | G2994: 20 | H2994: North Indian,Indian,Salads,Biryani,Chinese,Juices,Desserts | I2994: Austin Nagar | J2994: 77
A2995: 299869 | B2995: Koregaon Park | C2995: Pune | D2995: Foodiedoo | E2995: 500 | F2995: 2.9 | G2995: 80 | H2995: Punjabi | I2995: Kalyani Nagar | J2995: 59
A2996: 299951 | B2996: Taltala | C2996: Kolkata | D2996: New Noodle King | E2996: 300 | F2996: 4 | G2996: 100 | H2996: Chinese,Seafood | I2996: Esplanade | J2996: 53
... A3402: 329884 | B3402: New Malakpet | C3402: Hyderabad | D3402: Steves Kitchen | E3402: 200 | F3402: 3.7 | G3402: 50 | H3402: Chinese,Indian,Snacks | I3402: Kothapet & Dilsukhnagar | J3402: 48
A3403: 329976 | B3403: Golpark | C3403: Kolkata | D3403: 99 | E3403: 300 | F3403: 4.1 | G3403: 50 | H3403: Indian | I3403: South Kolkata | J3403: 77
A3404: 329990 | B3404: Thaltej | C3404: Ahmedabad | D3404: Chat On Chaat | E3404: 300 | F3404: 2.9 | G3404: 80 | H3404: Street Food,Chaat,Snacks,Fast Food | I3404: Vijay Cross Road | J3404: 47
A3405: 329996 | B3405: Lal Darwaja | C3405: Ahmedabad | D3405: Bera Samosa House | E3405: 150 | F3405: 2.9 | G3405: 80 | H3405: Street Food,Snacks | I3405: Laldarwaja | J3405: 40
A3406: 330061 | B3406: Jodhpur Village | C3406: Ahmedabad | D3406: Rajasthani Tadka | E3406: 300 | F3406: 4.5 | G3406: 100 | H3406: Indian | I3406: Prahlad Nagar | J3406: 49
A3407: 330209 | B3407: Navrangpura | C3407: Ahmedabad | D3407: Bean Box Cafe | E3407: 300 | F3407: 2.9 | G3407: 80 | H3407: Beverages,Continental,Desserts | I3407: Navrangpura | J3407: 37
A3408: 330317 | B3408: Erandwane | C3408: Pune | D3408: Food Junction | E3408: 300 | F3408: 2.9 | G3408: 80 | H3408: Indian | I3408: Kothrud | J3408: 46
A3409: 330456 | B3409: Toli Chowki | C3409: Hyderabad | D3409: Sounds Cheesy | E3409: 300 | F3409: 4.1 | G3409: 100 | H3409: Indian | I3409: Tolichowki | J3409: 73
A3410: 330495 | B3410: Garfa | C3410: Kolkata | D3410: Bangaliyana Ranna Ghar | E3410: 300 | F3410: 2.7 | G3410: 20 | H3410: Indian | I3410: Ruby Area | J3410: 80
A3411: 330536 | B3411: Santacruz East | C3411: Mumbai | D3411: New Bismillah Caterers | E3411: 300 | F3411: 3.6 | G3411: 20 | H3411: Biryani Indian | I3411: Scruz Bandra East | J3411: 36
A3412: 330550 | B3412: Purasawalkam | C3412: Chennai | D3412: Id (Contemporary South Indian) | E3412: 400 | F3412: 4.1 | G3412: 20 | H3412: South Indian,Beverages | I3412: Purasawalkam | J3412: 40
A3413: 330557 | B3413: Santacruz East | C3413: Mumbai | D3413: Second House Kitchen | E3413: 400 | F3413: 2.9 | G3413: 80 | H3413: Italian,Salads,Fast Food,Chinese | I3413: Kalina Santacruz East | J3413: 50
A3414: 330575 | B3414: Bidhannagar | C3414: Kolkata | D3414: Express By Ab'S | E3414: 300 | F3414: 4.5 | G3414: 20 | H3414: Barbecue,Biryani,Indian,Thalis | I3414: Sector V Salt Lake | J3414: 82
...

Sheet CLEAN DATA 
A1: ID | B1: Area | C1: City | D1: Restaurant | E1: Price | F1: Avg ratings | G1: Total ratings | H1: Food type | I1: Address | J1: Delivery time | K1: Price flag | L1: PRICE BUCKET | M1: PRIMARY FOOD TYPE | N1: DELIVERY TIME BRACKET
A2: 211 | B2: Koramangala | C2: Bangalore | D2: Tandoor Hut | E2: 300 | F2: 4.4 | G2: 100 | H2: Biryani,Chinese,North Indian,South Indian | I2: 5Th Block | J2: 59 | K2: =IF(E2=0,"outlier","valid") -> valid | L2: =IF(E2<=300,"BUDGET",IF(E2<=600,"MID","PREMIUM")) -> BUDGET | M2: =IFERROR(LEFT(H2, FIND(",", H2)-1), H2) -> Biryani | N2: {=_xlfn.IFS( G2<=25,"Fast", G2<=40,"Medium", G2>40,"Slow" )} -> Slow
A3: 221 | B3: Koramangala | C3: Bangalore | D3: Tunday Kababi | E3: 300 | F3: 4.1 | G3: 100 | H3: Mughlai,Lucknowi | I3: 5Th Block | J3: 56 | K3: =IF(E3=0,"outlier","valid") -> valid | L3: =IF(E3<=300,"BUDGET",IF(E3<=600,"MID","PREMIUM")) -> BUDGET | M3: =IFERROR(LEFT(H3, FIND(",", H3)-1), H3) -> Mughlai | N3: {=_xlfn.IFS( G3<=25,"Fast", G3<=40,"Medium", G3>40,"Slow" )} -> Slow
A4: 246 | B4: Jogupalya | C4: Bangalore | D4: Kim Lee | E4: 650 | F4: 4.4 | G4: 100 | H4: Chinese | I4: Double Road | J4: 50 | K4: =IF(E4=0,"outlier","valid") -> valid | L4: =IF(E4<=300,"BUDGET",IF(E4<=600,"MID","PREMIUM")) -> PREMIUM | M4: =IFERROR(LEFT(H4, FIND(",", H4)-1), H4) -> Chinese | N4: {=_xlfn.IFS( G4<=25,"Fast", G4<=40,"Medium", G4>40,"Slow" )} -> Slow
A5: 248 | B5: Indiranagar | C5: Bangalore | D5: New Punjabi Hotel | E5: 250 | F5: 3.9 | G5: 500 | H5: North Indian,Punjabi,Tandoor,Chinese | I5: 80 Feet Road | J5: 57 | K5: =IF(E5=0,"outlier","valid") -> valid | L5: =IF(E5<=300,"BUDGET",IF(E5<=600,"MID","PREMIUM")) -> BUDGET | M5: =IFERROR(LEFT(H5, FIND(",", H5)-1), H5) -> North Indian | N5: {=_xlfn.IFS( G5<=25,"Fast", G5<=40,"Medium", G5>40,"Slow" )} -> Slow
A6: 249 | B6: Indiranagar | C6: Bangalore | D6: Nh8 | E6: 350 | F6: 4 | G6: 50 | H6: Rajasthani,Gujarati,North Indian,Snacks,Desserts,Beverages,Thalis,Chaat | I6: 80 Feet Road | J6: 63 | K6: =IF(E6=0,"outlier","valid") -> valid | L6: =IF(E6<=300,"BUDGET",IF(E6<=600,"MID","PREMIUM")) -> MID | M6: =IFERROR(LEFT(H6, FIND(",", H6)-1), H6) -> Rajasthani | N6: {=_xlfn.IFS( G6<=25,"Fast", G6<=40,"Medium", G6>40,"Slow" )} -> Slow
A7: 254 | B7: Indiranagar | C7: Bangalore | D7: Treat | E7: 800 | F7: 4.5 | G7: 100 | H7: Mughlai,North Indian | I7: 100 Feet Road | J7: 56 | K7: =IF(E7=0,"outlier","valid") -> valid | L7: =IF(E7<=300,"BUDGET",IF(E7<=600,"MID","PREMIUM")) -> PREMIUM | M7: =IFERROR(LEFT(H7, FIND(",", H7)-1), H7) -> Mughlai | N7: {=_xlfn.IFS( G7<=25,"Fast", G7<=40,"Medium", G7>40,"Slow" )} -> Slow
A8: 258 | B8: Indiranagar | C8: Bangalore | D8: Chinita Real Mexican Food | E8: 1000 | F8: 4.5 | G8: 500 | H8: Mexican,Beverages,Salads | I8: Double Road | J8: 53 | K8: =IF(E8=0,"outlier","valid") -> valid | L8: =IF(E8<=300,"BUDGET",IF(E8<=600,"MID","PREMIUM")) -> PREMIUM | M8: =IFERROR(LEFT(H8, FIND(",", H8)-1), H8) -> Mexican | N8: {=_xlfn.IFS( G8<=25,"Fast", G8<=40,"Medium", G8>40,"Slow" )} -> Slow
A9: 263 | B9: Koramangala | C9: Bangalore | D9: Cupcake Noggins - Cakespastries And Desserts | E9: 150 | F9: 4.3 | G9: 100 | H9: Desserts,British,Bakery,Pizzas,Snacks | I9: 4Th Block | J9: 57 | K9: =IF(E9=0,"outlier","valid") -> valid | L9: =IF(E9<=300,"BUDGET",IF(E9<=600,"MID","PREMIUM")) -> BUDGET | M9: =IFERROR(LEFT(H9, FIND(",", H9)-1), H9) -> Desserts | N9: {=_xlfn.IFS( G9<=25,"Fast", G9<=40,"Medium", G9>40,"Slow" )} -> Slow
A10: 267 | B10: Domlur | C10: Bangalore | D10: Tea Brew | E10: 350 | F10: 4.1 | G10: 100 | H10: American,Italian,Beverages,Continental,Chinese,Pastas,Pizzas,Fast Food | I10: Double Road | J10: 57 | K10: =IF(E10=0,"outlier","valid") -> valid | L10: =IF(E10<=300,"BUDGET",IF(E10<=600,"MID","PREMIUM")) -> MID | M10: =IFERROR(LEFT(H10, FIND(",", H10)-1), H10) -> American | N10: {=_xlfn.IFS( G10<=25,"Fast", G10<=40,"Medium", G10>40,"Slow" )} -> Slow
A11: 308 | B11: Koramangala | C11: Bangalore | D11: Bangaliana | E11: 300 | F11: 4 | G11: 500 | H11: Bengali | I11: 7Th Block | J11: 57 | K11: =IF(E11=0,"outlier","valid") -> valid | L11: =IF(E11<=300,"BUDGET",IF(E11<=600,"MID","PREMIUM")) -> BUDGET | M11: =IFERROR(LEFT(H11, FIND(",", H11)-1), H11) -> Bengali | N11: {=_xlfn.IFS( G11<=25,"Fast", G11<=40,"Medium", G11>40,"Slow" )} -> Slow
A12: 435 | B12: Koramangala | C12: Bangalore | D12: Bamey'S Restro Cafe | E12: 400 | F12: 4.4 | G12: 100 | H12: Chinese,Thai,Nepalese | I12: 5Th Block | J12: 56 | K12: =IF(E12=0,"outlier","valid") -> valid | L12: =IF(E12<=300,"BUDGET",IF(E12<=600,"MID","PREMIUM")) -> MID | M12: =IFERROR(LEFT(H12, FIND(",", H12)-1), H12) -> Chinese | N12: {=_xlfn.IFS( G12<=25,"Fast", G12<=40,"Medium", G12>40,"Slow" )} -> Slow
A13: 446 | B13: Cooke Town | C13: Bangalore | D13: Altaf'S Chillies Restaurants | E13: 250 | F13: 4.3 | G13: 500 | H13: North Indian,Chinese | I13: Cooke Town | J13: 55 | K13: =IF(E13=0,"outlier","valid") -> valid | L13: =IF(E13<=300,"BUDGET",IF(E13<=600,"MID","PREMIUM")) -> BUDGET | M13: =IFERROR(LEFT(H13, FIND(",", H13)-1), H13) -> North Indian | N13: {=_xlfn.IFS( G13<=25,"Fast", G13<=40,"Medium", G13>40,"Slow" )} -> Slow
... A2982: 298694 | B2982: Camp | C2982: Pune | D2982: Ibaco | E2982: 800 | F2982: 2.9 | G2982: 80 | H2982: Ice Cream,Desserts | I2982: Camp | J2982: 35 | K2982: =IF(E2982=0,"outlier","valid") -> valid | L2982: =IF(E2982<=300,"BUDGET",IF(E2982<=600,"MID","PREMIUM")) -> PREMIUM | M2982: =IFERROR(LEFT(H2982, FIND(",", H2982)-1), H2982) -> Ice Cream | N2982: {=_xlfn.IFS( G2982<=25,"Fast", G2982<=40,"Medium", G2982>40,"Slow" )} -> Slow
A2983: 299150 | B2983: 26 | C2983: Chennai | D2983: Malabar Point | E2983: 450 | F2983: 4.2 | G2983: 100 | H2983: Biryani,Kerala,South Indian,Thalis | I2983: Alwarpet (Malabar Point) | J2983: 58 | K2983: =IF(E2983=0,"outlier","valid") -> valid | L2983: =IF(E2983<=300,"BUDGET",IF(E2983<=600,"MID","PREMIUM")) -> MID | M2983: =IFERROR(LEFT(H2983, FIND(",", H2983)-1), H2983) -> Biryani | N2983: {=_xlfn.IFS( G2983<=25,"Fast", G2983<=40,"Medium", G2983>40,"Slow" )} -> Slow
A2984: 299226 | B2984: Powai | C2984: Mumbai | D2984: Pratik Restaurant | E2984: 250 | F2984: 4.5 | G2984: 20 | H2984: Indian Chinese Tandoor Punjabi | I2984: Powai | J2984: 54 | K2984: =IF(E2984=0,"outlier","valid") -> valid | L2984: =IF(E2984<=300,"BUDGET",IF(E2984<=600,"MID","PREMIUM")) -> BUDGET | M2984: =IFERROR(LEFT(H2984, FIND(",", H2984)-1), H2984) -> Indian Chinese Tandoor Punjabi | N2984: {=_xlfn.IFS( G2984<=25,"Fast", G2984<=40,"Medium", G2984>40,"Slow" )} -> Fast
A2985: 299311 | B2985: Jamalia | C2985: Chennai | D2985: Waffle Dreams | E2985: 200 | F2985: 2.9 | G2985: 80 | H2985: Beverages,Desserts,Snacks | I2985: Perambur | J2985: 52 | K2985: =IF(E2985=0,"outlier","valid") -> valid | L2985: =IF(E2985<=300,"BUDGET",IF(E2985<=600,"MID","PREMIUM")) -> BUDGET | M2985: =IFERROR(LEFT(H2985, FIND(",", H2985)-1), H2985) -> Beverages | N2985: {=_xlfn.IFS( G2985<=25,"Fast", G2985<=40,"Medium", G2985>40,"Slow" )} -> Slow
A2986: 299312 | B2986: Rohini | C2986: Delhi | D2986: Meals And Bowls | E2986: 300 | F2986: 4 | G2986: 20 | H2986: North Indian,Punjabi,Mughlai,Home Food | I2986: Rohini | J2986: 36 | K2986: =IF(E2986=0,"outlier","valid") -> valid | L2986: =IF(E2986<=300,"BUDGET",IF(E2986<=600,"MID","PREMIUM")) -> BUDGET | M2986: =IFERROR(LEFT(H2986, FIND(",", H2986)-1), H2986) -> North Indian | N2986: {=_xlfn.IFS( G2986<=25,"Fast", G2986<=40,"Medium", G2986>40,"Slow" )} -> Fast
A2987: 299369 | B2987: Sec-9 Rohini | C2987: Delhi | D2987: Home Factory | E2987: 200 | F2987: 2.9 | G2987: 80 | H2987: North Indian,Continental,Chinese | I2987: Rohini | J2987: 50 | K2987: =IF(E2987=0,"outlier","valid") -> valid | L2987: =IF(E2987<=300,"BUDGET",IF(E2987<=600,"MID","PREMIUM")) -> BUDGET | M2987: =IFERROR(LEFT(H2987, FIND(",", H2987)-1), H2987) -> North Indian | N2987: {=_xlfn.IFS( G2987<=25,"Fast", G2987<=40,"Medium", G2987>40,"Slow" )} -> Slow
A2988: 299435 | B2988: Perambur | C2988: Chennai | D2988: Arabian Express | E2988: 300 | F2988: 4.4 | G2988: 20 | H2988: Indian,Arabian | I2988: Perambur | J2988: 65 | K2988: =IF(E2988=0,"outlier","valid") -> valid | L2988: =IF(E2988<=300,"BUDGET",IF(E2988<=600,"MID","PREMIUM")) -> BUDGET | M2988: =IFERROR(LEFT(H2988, FIND(",", H2988)-1), H2988) -> Indian | N2988: {=_xlfn.IFS( G2988<=25,"Fast", G2988<=40,"Medium", G2988>40,"Slow" )} -> Fast
A2989: 299501 | B2989: Machuabazar | C2989: Kolkata | D2989: Vanakkam | E2989: 300 | F2989: 4.4 | G2989: 50 | H2989: South Indian,Ice Cream | I2989: Maniktala | J2989: 49 | K2989: =IF(E2989=0,"outlier","valid") -> valid | L2989: =IF(E2989<=300,"BUDGET",IF(E2989<=600,"MID","PREMIUM")) -> BUDGET | M2989: =IFERROR(LEFT(H2989, FIND(",", H2989)-1), H2989) -> South Indian | N2989: {=_xlfn.IFS( G2989<=25,"Fast", G2989<=40,"Medium", G2989>40,"Slow" )} -> Slow
A2990: 299656 | B2990: Bidhannagar | C2990: Kolkata | D2990: Hatari | E2990: 500 | F2990: 4.5 | G2990: 500 | H2990: Chinese,Indian | I2990: Salt Lake | J2990: 73 | K2990: =IF(E2990=0,"outlier","valid") -> valid | L2990: =IF(E2990<=300,"BUDGET",IF(E2990<=600,"MID","PREMIUM")) -> MID | M2990: =IFERROR(LEFT(H2990, FIND(",", H2990)-1), H2990) -> Chinese | N2990: {=_xlfn.IFS( G2990<=25,"Fast", G2990<=40,"Medium", G2990>40,"Slow" )} -> Slow
A2991: 299680 | B2991: Kothrud | C2991: Pune | D2991: Box.72 | E2991: 200 | F2991: 2.9 | G2991: 80 | H2991: Fast Food,Chinese,Indian | I2991: Kothrud | J2991: 49 | K2991: =IF(E2991=0,"outlier","valid") -> valid | L2991: =IF(E2991<=300,"BUDGET",IF(E2991<=600,"MID","PREMIUM")) -> BUDGET | M2991: =IFERROR(LEFT(H2991, FIND(",", H2991)-1), H2991) -> Fast Food | N2991: {=_xlfn.IFS( G2991<=25,"Fast", G2991<=40,"Medium", G2991>40,"Slow" )} -> Slow
A2992: 299750 | B2992: Alwarpet | C2992: Chennai | D2992: Dakshin At Crowne Plaza Chennai | E2992: 300 | F2992: 4.5 | G2992: 20 | H2992: North Indian,Indian,Salads,Biryani,Chinese,Juices,Desserts | I2992: Austin Nagar | J2992: 69 | K2992: =IF(E2992=0,"outlier","valid") -> valid | L2992: =IF(E2992<=300,"BUDGET",IF(E2992<=600,"MID","PREMIUM")) -> BUDGET | M2992: =IFERROR(LEFT(H2992, FIND(",", H2992)-1), H2992) -> North Indian | N2992: {=_xlfn.IFS( G2992<=25,"Fast", G2992<=40,"Medium", G2992>40,"Slow" )} -> Fast
A2993: 299751 | B2993: Alwarpet | C2993: Chennai | D2993: Cappuccino At Crowne Plaza Chennai | E2993: 300 | F2993: 4.5 | G2993: 20 | H2993: North Indian,Indian,Salads,Biryani,Chinese,Juices,Desserts | I2993: Austin Nagar | J2993: 77 | K2993: =IF(E2993=0,"outlier","valid") -> valid | L2993: =IF(E2993<=300,"BUDGET",IF(E2993<=600,"MID","PREMIUM")) -> BUDGET | M2993: =IFERROR(LEFT(H2993, FIND(",", H2993)-1), H2993) -> North Indian | N2993: {=_xlfn.IFS( G2993<=25,"Fast", G2993<=40,"Medium", G2993>40,"Slow" )} -> Fast
A2994: 299869 | B2994: Koregaon Park | C2994: Pune | D2994: Foodiedoo | E2994: 500 | F2994: 2.9 | G2994: 80 | H2994: Punjabi | I2994: Kalyani Nagar | J2994: 59 | K2994: =IF(E2994=0,"outlier","valid") -> valid | L2994: =IF(E2994<=300,"BUDGET",IF(E2994<=600,"MID","PREMIUM")) -> MID | M2994: =IFERROR(LEFT(H2994, FIND(",", H2994)-1), H2994) -> Punjabi | N2994: {=_xlfn.IFS( G2994<=25,"Fast", G2994<=40,"Medium", G2994>40,"Slow" )} -> Slow
